Workbook
Name DateValide: OFFSET(DataGraph!$E$3,0,0,COUNTIF(DataGraph!$E$3:$E$242,"<>"),1)
Name InvestissementTotValide: OFFSET(DataGraph!$G$3,0,0,COUNTIF(DataGraph!$G$3:$G$242,"<>"),1)

Sheet DashBoard
B2: Tableau de Bord Épargne
B4: ='Mise en épargne'!I1 -> 0 | D4: ='Mise en épargne'!O2 -> 0 | F4: =AVERAGE('Mise en épargne'!B5:M24) -> 0 | H4: =LOOKUP(9^9,'Mise en épargne'!O29:O48) -> #N/A
B7: Épargne Totale | D7: % Objectif Atteint | F7: Versement Mensuel | H7: %Salaire Moyen Sur l'année En cours
B8: ='Mise en épargne'!C1 -> 500000 | D8: ='Mise en épargne'!L1-'Mise en épargne'!F1 -> 0 | F8: =(SUM('Livret Jeune'!G1+'Livret A'!G1+'Trade Republique'!G1+Participation!G1+'Assurance Vie'!G1)-(SUM('Mise en épargne'!B5:M24)+'Mise en épargne'!F2))/(SUM('Mise en épargne'!B5:M24)+'Mise en épargne'!F2) -> #DIV/0! | H8: ='Trade Republique'!J1 -> #DIV/0!
B11: Objectif Long Terme | D11: Gains Cumulés | F11: Rendement Global (%) | H11: Rendement TR (%)
B12: 📈 Évolution de l’épargne | F12: 🧩 Répartition des supports

Sheet Mise en épargne
B1: Objectif | C1: 500000 | E1: Mise Actuelle | F1: =SUM(B5:M24) -> 0 | H1: épargne actuelle | I1: ='Livret Jeune'!G1+'Livret A'!G1+'Trade Republique'!G1 + Participation!G1 + 'Assurance Vie'!G1 -> 0 | K1: épargne accumulée | L1: =I1-'Livret Jeune'!D1-'Livret A'!D1 -Participation!D1 -'Assurance Vie'!D1 -> 0 | N1: évolution | O1: =(L1-F1)/F1 -> #DIV/0! | T1: Répartition | U1: Total | V1: ='Livret Jeune'!B1 -> Livret Jeune | W1: ='Livret A'!B1 -> Livret A | X1: ='Trade Republique'!B1 -> Trade Republique | Y1: =Participation!B1 -> Participation | Z1: Assurance Vie
E2: Départ | F2: =SUM('Livret Jeune'!D1,'Livret A'!D1,'Trade Republique'!D1,Participation!D1, 'Assurance Vie'!D1) -> 0 | N2: % Objectif | O2: =I1/C1 -> 0 | U2: =I1 -> 0 | V2: ='Livret Jeune'!G1 -> 0 | W2: ='Livret A'!G1 -> 0 | X2: ='Trade Republique'!G1 -> 0 | Y2: =Participation!G1 -> 0 | Z2: ='Assurance Vie'!G1 -> 0
A4: Année | B4: Janvier | C4: Février | D4: Mars | E4: Avril | F4: Mai | G4: Juin | H4: Juillet | I4: Aout | J4: Septembre | K4: Octobre | L4: Novembre | M4: Décembre | N4: Total Sur l'année | O4: Évolution annuelle sans TR | P4: Évolution Annuelle avec TR
A5: 2024 | B5: =IF(COUNTA('Livret Jeune'!B5, 'Livret A'!B5, 'Trade Republique'!B5, Participation!B5, 'Assurance Vie'!B5)=0, "", SUM('Livret Jeune'!B5, 'Livret A'!B5, 'Trade Republique'!B5, Participation!B5, 'Assurance Vie'!B5)) -> 0 | C5: =IF(COUNTA('Livret Jeune'!C5, 'Livret A'!C5, 'Trade Republique'!C5, Participation!C5, 'Assurance Vie'!C5)=0, "", SUM('Livret Jeune'!C5, 'Livret A'!C5, 'Trade Republique'!C5, Participation!C5, 'Assurance Vie'!C5)) -> 0 | D5: =IF(COUNTA('Livret Jeune'!D5, 'Livret A'!D5, 'Trade Republique'!D5, Participation!D5, 'Assurance Vie'!D5)=0, "", SUM('Livret Jeune'!D5, 'Livret A'!D5, 'Trade Republique'!D5, Participation!D5, 'Assurance Vie'!D5)) -> 0 | E5: =IF(COUNTA('Livret Jeune'!E5, 'Livret A'!E5, 'Trade Republique'!E5, Participation!E5, 'Assurance Vie'!E5)=0, "", SUM('Livret Jeune'!E5, 'Livret A'!E5, 'Trade Republique'!E5, Participation!E5, 'Assurance Vie'!E5)) -> 0 | F5: =IF(COUNTA('Livret Jeune'!F5, 'Livret A'!F5, 'Trade Republique'!F5, Participation!F5, 'Assurance Vie'!F5)=0, "", SUM('Livret Jeune'!F5, 'Livret A'!F5, 'Trade Republique'!F5, Participation!F5, 'Assurance Vie'!F5)) -> 0 | G5: =IF(COUNTA('Livret Jeune'!G5, 'Livret A'!G5, 'Trade Republique'!G5, Participation!G5, 'Assurance Vie'!G5)=0, "", SUM('Livret Jeune'!G5, 'Livret A'!G5, 'Trade Republique'!G5, Participation!G5, 'Assurance Vie'!G5)) -> 0 | H5: =IF(COUNTA('Livret Jeune'!H5, 'Livret A'!H5, 'Trade Republique'!H5, Participation!H5, 'Assurance Vie'!H5)=0, "", SUM('Livret Jeune'!H5, 'Livret A'!H5, 'Trade Republique'!H5, Participation!H5, 'Assurance Vie'!H5)) -> 0 | I5: =IF(COUNTA('Livret Jeune'!I5, 'Livret A'!I5, 'Trade Republique'!I5, Participation!I5, 'Assurance Vie'!I5)=0, "", SUM('Livret Jeune'!I5, 'Livret A'!I5, 'Trade Republique'!I5, Participation!I5, 'Assurance Vie'!I5)) -> 0 | ... M5: =IF(COUNTA('Livret Jeune'!M5, 'Livret A'!M5, 'Trade Republique'!M5, Participation!M5, 'Assurance Vie'!M5)=0, "", SUM('Livret Jeune'!M5, 'Livret A'!M5, 'Trade Republique'!M5, Participation!M5, 'Assurance Vie'!M5)) -> 0 | N5: =SUM(B5:M5) -> 0 | O5: =(SUM('Livret Jeune'!B5:N5)+SUM('Livret A'!B5:N5) + SUM(Participation!B5:N5) -(SUM('Livret Jeune'!B5:M5) +SUM('Livret A'!B5:M5) - SUM(Participation!B5:M5) ))/(SUM('Livret Jeune'!B5:M5) +SUM('Livret A'!B5:M5) + SUM(Participation!B5:M5)) -> #DIV/0! | P5: =(SUM('Livret Jeune'!B5:N5)+SUM('Livret A'!B5:N5) + SUM(Participation!B5:N5) +('Trade Republique'!N52+'Trade Republique'!N103)-(SUM('Livret Jeune'!B5:M5)+SUM('Livret A'!B5:M5) + SUM(Participation!B5:M5) +'Trade Republique'!N5))/(SUM('Livret Jeune'!B5:M5)+SUM('Livret A'!B5:M5)+('Trade Republique'!N5) + SUM(Participation!B5:N5) ) -> #DIV/0!
A6: 2025 | B6: =IF(COUNTA('Livret Jeune'!B6, 'Livret A'!B6, 'Trade Republique'!B6, Participation!B6, 'Assurance Vie'!B6)=0, "", SUM('Livret Jeune'!B6, 'Livret A'!B6, 'Trade Republique'!B6, Participation!B6, 'Assurance Vie'!B6)) -> 0 | C6: =IF(COUNTA('Livret Jeune'!C6, 'Livret A'!C6, 'Trade Republique'!C6, Participation!C6, 'Assurance Vie'!C6)=0, "", SUM('Livret Jeune'!C6, 'Livret A'!C6, 'Trade Republique'!C6, Participation!C6, 'Assurance Vie'!C6)) -> 0 | D6: =IF(COUNTA('Livret Jeune'!D6, 'Livret A'!D6, 'Trade Republique'!D6, Participation!D6, 'Assurance Vie'!D6)=0, "", SUM('Livret Jeune'!D6, 'Livret A'!D6, 'Trade Republique'!D6, Participation!D6, 'Assurance Vie'!D6)) -> 0 | E6: =IF(COUNTA('Livret Jeune'!E6, 'Livret A'!E6, 'Trade Republique'!E6, Participation!E6, 'Assurance Vie'!E6)=0, "", SUM('Livret Jeune'!E6, 'Livret A'!E6, 'Trade Republique'!E6, Participation!E6, 'Assurance Vie'!E6)) -> 0 | F6: =IF(COUNTA('Livret Jeune'!F6, 'Livret A'!F6, 'Trade Republique'!F6, Participation!F6, 'Assurance Vie'!F6)=0, "", SUM('Livret Jeune'!F6, 'Livret A'!F6, 'Trade Republique'!F6, Participation!F6, 'Assurance Vie'!F6)) -> 0 | G6: =IF(COUNTA('Livret Jeune'!G6, 'Livret A'!G6, 'Trade Republique'!G6, Participation!G6, 'Assurance Vie'!G6)=0, "", SUM('Livret Jeune'!G6, 'Livret A'!G6, 'Trade Republique'!G6, Participation!G6, 'Assurance Vie'!G6)) -> 0 | H6: =IF(COUNTA('Livret Jeune'!H6, 'Livret A'!H6, 'Trade Republique'!H6, Participation!H6, 'Assurance Vie'!H6)=0, "", SUM('Livret Jeune'!H6, 'Livret A'!H6, 'Trade Republique'!H6, Participation!H6, 'Assurance Vie'!H6)) -> 0 | I6: =IF(COUNTA('Livret Jeune'!I6, 'Livret A'!I6, 'Trade Republique'!I6, Participation!I6, 'Assurance Vie'!I6)=0, "", SUM('Livret Jeune'!I6, 'Livret A'!I6, 'Trade Republique'!I6, Participation!I6, 'Assurance Vie'!I6)) -> 0 | ... M6: =IF(COUNTA('Livret Jeune'!M6, 'Livret A'!M6, 'Trade Republique'!M6, Participation!M6, 'Assurance Vie'!M6)=0, "", SUM('Livret Jeune'!M6, 'Livret A'!M6, 'Trade Republique'!M6, Participation!M6, 'Assurance Vie'!M6)) -> 0 | N6: =SUM(B6:M6) -> 0 | O6: =(SUM('Livret Jeune'!B6:N6)+SUM('Livret A'!B6:N6)+SUM(Participation!B6:N6) - (SUM('Livret Jeune'!B6:M6) +SUM('Livret A'!B6:M6) + SUM(Participation!B6:M6) ))/(SUM('Livret Jeune'!B6:M6) +SUM('Livret A'!B6:M6) + SUM(Participation!B6:M6)) -> #DIV/0! | P6: =(SUM('Livret Jeune'!B6:N6)+SUM('Livret A'!B6:N6)+ SUM(Participation!B6:N6)+('Trade Republique'!N53+'Trade Republique'!N104-'Trade Republique'!N103) -(SUM('Livret Jeune'!B6:M6)+SUM('Livret A'!B6:M6)+'Trade Republique'!N6 + SUM(Participation!B6:M6)))/(SUM('Livret Jeune'!B6:M6)+SUM('Livret A'!B6:M6)+('Trade Republique'!N6)+ SUM(Participation!B6:M6)) -> #DIV/0!
A7: 2026 | B7: =IF(COUNTA('Livret Jeune'!B7, 'Livret A'!B7, 'Trade Republique'!B7, Participation!B7, 'Assurance Vie'!B7)=0, "", SUM('Livret Jeune'!B7, 'Livret A'!B7, 'Trade Republique'!B7, Participation!B7, 'Assurance Vie'!B7)) -> 0 | C7: =IF(COUNTA('Livret Jeune'!C7, 'Livret A'!C7, 'Trade Republique'!C7, Participation!C7, 'Assurance Vie'!C7)=0, "", SUM('Livret Jeune'!C7, 'Livret A'!C7, 'Trade Republique'!C7, Participation!C7, 'Assurance Vie'!C7)) -> 0 | D7: =IF(COUNTA('Livret Jeune'!D7, 'Livret A'!D7, 'Trade Republique'!D7, Participation!D7, 'Assurance Vie'!D7)=0, "", SUM('Livret Jeune'!D7, 'Livret A'!D7, 'Trade Republique'!D7, Participation!D7, 'Assurance Vie'!D7)) -> 0 | E7: =IF(COUNTA('Livret Jeune'!E7, 'Livret A'!E7, 'Trade Republique'!E7, Participation!E7, 'Assurance Vie'!E7)=0, "", SUM('Livret Jeune'!E7, 'Livret A'!E7, 'Trade Republique'!E7, Participation!E7, 'Assurance Vie'!E7)) -> 0 | F7: =IF(COUNTA('Livret Jeune'!F7, 'Livret A'!F7, 'Trade Republique'!F7, Participation!F7, 'Assurance Vie'!F7)=0, "", SUM('Livret Jeune'!F7, 'Livret A'!F7, 'Trade Republique'!F7, Participation!F7, 'Assurance Vie'!F7)) -> 0 | G7: =IF(COUNTA('Livret Jeune'!G7, 'Livret A'!G7, 'Trade Republique'!G7, Participation!G7, 'Assurance Vie'!G7)=0, "", SUM('Livret Jeune'!G7, 'Livret A'!G7, 'Trade Republique'!G7, Participation!G7, 'Assurance Vie'!G7)) -> 0 | H7: =IF(COUNTA('Livret Jeune'!H7, 'Livret A'!H7, 'Trade Republique'!H7, Participation!H7, 'Assurance Vie'!H7)=0, "", SUM('Livret Jeune'!H7, 'Livret A'!H7, 'Trade Republique'!H7, Participation!H7, 'Assurance Vie'!H7)) | I7: =IF(COUNTA('Livret Jeune'!I7, 'Livret A'!I7, 'Trade Republique'!I7, Participation!I7, 'Assurance Vie'!I7)=0, "", SUM('Livret Jeune'!I7, 'Livret A'!I7, 'Trade Republique'!I7, Participation!I7, 'Assurance Vie'!I7)) | ... M7: =IF(COUNTA('Livret Jeune'!M7, 'Livret A'!M7, 'Trade Republique'!M7, Participation!M7, 'Assurance Vie'!M7)=0, "", SUM('Livret Jeune'!M7, 'Livret A'!M7, 'Trade Republique'!M7, Participation!M7, 'Assurance Vie'!M7)) | N7: =SUM(B7:M7) -> 0
A8: 2027 | B8: =IF(COUNTA('Livret Jeune'!B8, 'Livret A'!B8, 'Trade Republique'!B8, Participation!B8, 'Assurance Vie'!B8)=0, "", SUM('Livret Jeune'!B8, 'Livret A'!B8, 'Trade Republique'!B8, Participation!B8, 'Assurance Vie'!B8)) | C8: =IF(COUNTA('Livret Jeune'!C8, 'Livret A'!C8, 'Trade Republique'!C8, Participation!C8, 'Assurance Vie'!C8)=0, "", SUM('Livret Jeune'!C8, 'Livret A'!C8, 'Trade Republique'!C8, Participation!C8, 'Assurance Vie'!C8)) | D8: =IF(COUNTA('Livret Jeune'!D8, 'Livret A'!D8, 'Trade Republique'!D8, Participation!D8, 'Assurance Vie'!D8)=0, "", SUM('Livret Jeune'!D8, 'Livret A'!D8, 'Trade Republique'!D8, Participation!D8, 'Assurance Vie'!D8)) | E8: =IF(COUNTA('Livret Jeune'!E8, 'Livret A'!E8, 'Trade Republique'!E8, Participation!E8, 'Assurance Vie'!E8)=0, "", SUM('Livret Jeune'!E8, 'Livret A'!E8, 'Trade Republique'!E8, Participation!E8, 'Assurance Vie'!E8)) | F8: =IF(COUNTA('Livret Jeune'!F8, 'Livret A'!F8, 'Trade Republique'!F8, Participation!F8, 'Assurance Vie'!F8)=0, "", SUM('Livret Jeune'!F8, 'Livret A'!F8, 'Trade Republique'!F8, Participation!F8, 'Assurance Vie'!F8)) | G8: =IF(COUNTA('Livret Jeune'!G8, 'Livret A'!G8, 'Trade Republique'!G8, Participation!G8, 'Assurance Vie'!G8)=0, "", SUM('Livret Jeune'!G8, 'Livret A'!G8, 'Trade Republique'!G8, Participation!G8, 'Assurance Vie'!G8)) | H8: =IF(COUNTA('Livret Jeune'!H8, 'Livret A'!H8, 'Trade Republique'!H8, Participation!H8, 'Assurance Vie'!H8)=0, "", SUM('Livret Jeune'!H8, 'Livret A'!H8, 'Trade Republique'!H8, Participation!H8, 'Assurance Vie'!H8)) | I8: =IF(COUNTA('Livret Jeune'!I8, 'Livret A'!I8, 'Trade Republique'!I8, Participation!I8, 'Assurance Vie'!I8)=0, "", SUM('Livret Jeune'!I8, 'Livret A'!I8, 'Trade Republique'!I8, Participation!I8, 'Assurance Vie'!I8)) | ... M8: =IF(COUNTA('Livret Jeune'!M8, 'Livret A'!M8, 'Trade Republique'!M8, Participation!M8, 'Assurance Vie'!M8)=0, "", SUM('Livret Jeune'!M8, 'Livret A'!M8, 'Trade Republique'!M8, Participation!M8, 'Assurance Vie'!M8)) | N8: =SUM(B8:M8) -> 0
A9: 2028 | B9: =IF(COUNTA('Livret Jeune'!B9, 'Livret A'!B9, 'Trade Republique'!B9, Participation!B9, 'Assurance Vie'!B9)=0, "", SUM('Livret Jeune'!B9, 'Livret A'!B9, 'Trade Republique'!B9, Participation!B9, 'Assurance Vie'!B9)) | C9: =IF(COUNTA('Livret Jeune'!C9, 'Livret A'!C9, 'Trade Republique'!C9, Participation!C9, 'Assurance Vie'!C9)=0, "", SUM('Livret Jeune'!C9, 'Livret A'!C9, 'Trade Republique'!C9, Participation!C9, 'Assurance Vie'!C9)) | D9: =IF(COUNTA('Livret Jeune'!D9, 'Livret A'!D9, 'Trade Republique'!D9, Participation!D9, 'Assurance Vie'!D9)=0, "", SUM('Livret Jeune'!D9, 'Livret A'!D9, 'Trade Republique'!D9, Participation!D9, 'Assurance Vie'!D9)) | E9: =IF(COUNTA('Livret Jeune'!E9, 'Livret A'!E9, 'Trade Republique'!E9, Participation!E9, 'Assurance Vie'!E9)=0, "", SUM('Livret Jeune'!E9, 'Livret A'!E9, 'Trade Republique'!E9, Participation!E9, 'Assurance Vie'!E9)) | F9: =IF(COUNTA('Livret Jeune'!F9, 'Livret A'!F9, 'Trade Republique'!F9, Participation!F9, 'Assurance Vie'!F9)=0, "", SUM('Livret Jeune'!F9, 'Livret A'!F9, 'Trade Republique'!F9, Participation!F9, 'Assurance Vie'!F9)) | G9: =IF(COUNTA('Livret Jeune'!G9, 'Livret A'!G9, 'Trade Republique'!G9, Participation!G9, 'Assurance Vie'!G9)=0, "", SUM('Livret Jeune'!G9, 'Livret A'!G9, 'Trade Republique'!G9, Participation!G9, 'Assurance Vie'!G9)) | H9: =IF(COUNTA('Livret Jeune'!H9, 'Livret A'!H9, 'Trade Republique'!H9, Participation!H9, 'Assurance Vie'!H9)=0, "", SUM('Livret Jeune'!H9, 'Livret A'!H9, 'Trade Republique'!H9, Participation!H9, 'Assurance Vie'!H9)) | I9: =IF(COUNTA('Livret Jeune'!I9, 'Livret A'!I9, 'Trade Republique'!I9, Participation!I9, 'Assurance Vie'!I9)=0, "", SUM('Livret Jeune'!I9, 'Livret A'!I9, 'Trade Republique'!I9, Participation!I9, 'Assurance Vie'!I9)) | ... M9: =IF(COUNTA('Livret Jeune'!M9, 'Livret A'!M9, 'Trade Republique'!M9, Participation!M9, 'Assurance Vie'!M9)=0, "", SUM('Livret Jeune'!M9, 'Livret A'!M9, 'Trade Republique'!M9, Participation!M9, 'Assurance Vie'!M9)) | N9: =SUM(B9:M9) -> 0
A10: 2029 | B10: =IF(COUNTA('Livret Jeune'!B10, 'Livret A'!B10, 'Trade Republique'!B10, Participation!B10, 'Assurance Vie'!B10)=0, "", SUM('Livret Jeune'!B10, 'Livret A'!B10, 'Trade Republique'!B10, Participation!B10, 'Assurance Vie'!B10)) | C10: =IF(COUNTA('Livret Jeune'!C10, 'Livret A'!C10, 'Trade Republique'!C10, Participation!C10, 'Assurance Vie'!C10)=0, "", SUM('Livret Jeune'!C10, 'Livret A'!C10, 'Trade Republique'!C10, Participation!C10, 'Assurance Vie'!C10)) | D10: =IF(COUNTA('Livret Jeune'!D10, 'Livret A'!D10, 'Trade Republique'!D10, Participation!D10, 'Assurance Vie'!D10)=0, "", SUM('Livret Jeune'!D10, 'Livret A'!D10, 'Trade Republique'!D10, Participation!D10, 'Assurance Vie'!D10)) | E10: =IF(COUNTA('Livret Jeune'!E10, 'Livret A'!E10, 'Trade Republique'!E10, Participation!E10, 'Assurance Vie'!E10)=0, "", SUM('Livret Jeune'!E10, 'Livret A'!E10, 'Trade Republique'!E10, Participation!E10, 'Assurance Vie'!E10)) | F10: =IF(COUNTA('Livret Jeune'!F10, 'Livret A'!F10, 'Trade Republique'!F10, Participation!F10, 'Assurance Vie'!F10)=0, "", SUM('Livret Jeune'!F10, 'Livret A'!F10, 'Trade Republique'!F10, Participation!F10, 'Assurance Vie'!F10)) | G10: =IF(COUNTA('Livret Jeune'!G10, 'Livret A'!G10, 'Trade Republique'!G10, Participation!G10, 'Assurance Vie'!G10)=0, "", SUM('Livret Jeune'!G10, 'Livret A'!G10, 'Trade Republique'!G10, Participation!G10, 'Assurance Vie'!G10)) | H10: =IF(COUNTA('Livret Jeune'!H10, 'Livret A'!H10, 'Trade Republique'!H10, Participation!H10, 'Assurance Vie'!H10)=0, "", SUM('Livret Jeune'!H10, 'Livret A'!H10, 'Trade Republique'!H10, Participation!H10, 'Assurance Vie'!H10)) | I10: =IF(COUNTA('Livret Jeune'!I10, 'Livret A'!I10, 'Trade Republique'!I10, Participation!I10, 'Assurance Vie'!I10)=0, "", SUM('Livret Jeune'!I10, 'Livret A'!I10, 'Trade Republique'!I10, Participation!I10, 'Assurance Vie'!I10)) | ... M10: =IF(COUNTA('Livret Jeune'!M10, 'Livret A'!M10, 'Trade Republique'!M10, Participation!M10, 'Assurance Vie'!M10)=0, "", SUM('Livret Jeune'!M10, 'Livret A'!M10, 'Trade Republique'!M10, Participation!M10, 'Assurance Vie'!M10)) | N10: =SUM(B10:M10) -> 0
A11: 2030 | B11: =IF(COUNTA('Livret Jeune'!B11, 'Livret A'!B11, 'Trade Republique'!B11, Participation!B11, 'Assurance Vie'!B11)=0, "", SUM('Livret Jeune'!B11, 'Livret A'!B11, 'Trade Republique'!B11, Participation!B11, 'Assurance Vie'!B11)) | C11: =IF(COUNTA('Livret Jeune'!C11, 'Livret A'!C11, 'Trade Republique'!C11, Participation!C11, 'Assurance Vie'!C11)=0, "", SUM('Livret Jeune'!C11, 'Livret A'!C11, 'Trade Republique'!C11, Participation!C11, 'Assurance Vie'!C11)) | D11: =IF(COUNTA('Livret Jeune'!D11, 'Livret A'!D11, 'Trade Republique'!D11, Participation!D11, 'Assurance Vie'!D11)=0, "", SUM('Livret Jeune'!D11, 'Livret A'!D11, 'Trade Republique'!D11, Participation!D11, 'Assurance Vie'!D11)) | E11: =IF(COUNTA('Livret Jeune'!E11, 'Livret A'!E11, 'Trade Republique'!E11, Participation!E11, 'Assurance Vie'!E11)=0, "", SUM('Livret Jeune'!E11, 'Livret A'!E11, 'Trade Republique'!E11, Participation!E11, 'Assurance Vie'!E11)) | F11: =IF(COUNTA('Livret Jeune'!F11, 'Livret A'!F11, 'Trade Republique'!F11, Participation!F11, 'Assurance Vie'!F11)=0, "", SUM('Livret Jeune'!F11, 'Livret A'!F11, 'Trade Republique'!F11, Participation!F11, 'Assurance Vie'!F11)) | G11: =IF(COUNTA('Livret Jeune'!G11, 'Livret A'!G11, 'Trade Republique'!G11, Participation!G11, 'Assurance Vie'!G11)=0, "", SUM('Livret Jeune'!G11, 'Livret A'!G11, 'Trade Republique'!G11, Participation!G11, 'Assurance Vie'!G11)) | H11: =IF(COUNTA('Livret Jeune'!H11, 'Livret A'!H11, 'Trade Republique'!H11, Participation!H11, 'Assurance Vie'!H11)=0, "", SUM('Livret Jeune'!H11, 'Livret A'!H11, 'Trade Republique'!H11, Participation!H11, 'Assurance Vie'!H11)) | I11: =IF(COUNTA('Livret Jeune'!I11, 'Livret A'!I11, 'Trade Republique'!I11, Participation!I11, 'Assurance Vie'!I11)=0, "", SUM('Livret Jeune'!I11, 'Livret A'!I11, 'Trade Republique'!I11, Participation!I11, 'Assurance Vie'!I11)) | ... M11: =IF(COUNTA('Livret Jeune'!M11, 'Livret A'!M11, 'Trade Republique'!M11, Participation!M11, 'Assurance Vie'!M11)=0, "", SUM('Livret Jeune'!M11, 'Livret A'!M11, 'Trade Republique'!M11, Participation!M11, 'Assurance Vie'!M11)) | N11: =SUM(B11:M11) -> 0
A12: 2031 | B12: =IF(COUNTA('Livret Jeune'!B12, 'Livret A'!B12, 'Trade Republique'!B12, Participation!B12, 'Assurance Vie'!B12)=0, "", SUM('Livret Jeune'!B12, 'Livret A'!B12, 'Trade Republique'!B12, Participation!B12, 'Assurance Vie'!B12)) | C12: =IF(COUNTA('Livret Jeune'!C12, 'Livret A'!C12, 'Trade Republique'!C12, Participation!C12, 'Assurance Vie'!C12)=0, "", SUM('Livret Jeune'!C12, 'Livret A'!C12, 'Trade Republique'!C12, Participation!C12, 'Assurance Vie'!C12)) | D12: =IF(COUNTA('Livret Jeune'!D12, 'Livret A'!D12, 'Trade Republique'!D12, Participation!D12, 'Assurance Vie'!D12)=0, "", SUM('Livret Jeune'!D12, 'Livret A'!D12, 'Trade Republique'!D12, Participation!D12, 'Assurance Vie'!D12)) | E12: =IF(COUNTA('Livret Jeune'!E12, 'Livret A'!E12, 'Trade Republique'!E12, Participation!E12, 'Assurance Vie'!E12)=0, "", SUM('Livret Jeune'!E12, 'Livret A'!E12, 'Trade Republique'!E12, Participation!E12, 'Assurance Vie'!E12)) | F12: =IF(COUNTA('Livret Jeune'!F12, 'Livret A'!F12, 'Trade Republique'!F12, Participation!F12, 'Assurance Vie'!F12)=0, "", SUM('Livret Jeune'!F12, 'Livret A'!F12, 'Trade Republique'!F12, Participation!F12, 'Assurance Vie'!F12)) | G12: =IF(COUNTA('Livret Jeune'!G12, 'Livret A'!G12, 'Trade Republique'!G12, Participation!G12, 'Assurance Vie'!G12)=0, "", SUM('Livret Jeune'!G12, 'Livret A'!G12, 'Trade Republique'!G12, Participation!G12, 'Assurance Vie'!G12)) | H12: =IF(COUNTA('Livret Jeune'!H12, 'Livret A'!H12, 'Trade Republique'!H12, Participation!H12, 'Assurance Vie'!H12)=0, "", SUM('Livret Jeune'!H12, 'Livret A'!H12, 'Trade Republique'!H12, Participation!H12, 'Assurance Vie'!H12)) | I12: =IF(COUNTA('Livret Jeune'!I12, 'Livret A'!I12, 'Trade Republique'!I12, Participation!I12, 'Assurance Vie'!I12)=0, "", SUM('Livret Jeune'!I12, 'Livret A'!I12, 'Trade Republique'!I12, Participation!I12, 'Assurance Vie'!I12)) | ... M12: =IF(COUNTA('Livret Jeune'!M12, 'Livret A'!M12, 'Trade Republique'!M12, Participation!M12, 'Assurance Vie'!M12)=0, "", SUM('Livret Jeune'!M12, 'Livret A'!M12, 'Trade Republique'!M12, Participation!M12, 'Assurance Vie'!M12)) | N12: =SUM(B12:M12) -> 0
A13: 2032 | B13: =IF(COUNTA('Livret Jeune'!B13, 'Livret A'!B13, 'Trade Republique'!B13, Participation!B13, 'Assurance Vie'!B13)=0, "", SUM('Livret Jeune'!B13, 'Livret A'!B13, 'Trade Republique'!B13, Participation!B13, 'Assurance Vie'!B13)) | C13: =IF(COUNTA('Livret Jeune'!C13, 'Livret A'!C13, 'Trade Republique'!C13, Participation!C13, 'Assurance Vie'!C13)=0, "", SUM('Livret Jeune'!C13, 'Livret A'!C13, 'Trade Republique'!C13, Participation!C13, 'Assurance Vie'!C13)) | D13: =IF(COUNTA('Livret Jeune'!D13, 'Livret A'!D13, 'Trade Republique'!D13, Participation!D13, 'Assurance Vie'!D13)=0, "", SUM('Livret Jeune'!D13, 'Livret A'!D13, 'Trade Republique'!D13, Participation!D13, 'Assurance Vie'!D13)) | E13: =IF(COUNTA('Livret Jeune'!E13, 'Livret A'!E13, 'Trade Republique'!E13, Participation!E13, 'Assurance Vie'!E13)=0, "", SUM('Livret Jeune'!E13, 'Livret A'!E13, 'Trade Republique'!E13, Participation!E13, 'Assurance Vie'!E13)) | F13: =IF(COUNTA('Livret Jeune'!F13, 'Livret A'!F13, 'Trade Republique'!F13, Participation!F13, 'Assurance Vie'!F13)=0, "", SUM('Livret Jeune'!F13, 'Livret A'!F13, 'Trade Republique'!F13, Participation!F13, 'Assurance Vie'!F13)) | G13: =IF(COUNTA('Livret Jeune'!G13, 'Livret A'!G13, 'Trade Republique'!G13, Participation!G13, 'Assurance Vie'!G13)=0, "", SUM('Livret Jeune'!G13, 'Livret A'!G13, 'Trade Republique'!G13, Participation!G13, 'Assurance Vie'!G13)) | H13: =IF(COUNTA('Livret Jeune'!H13, 'Livret A'!H13, 'Trade Republique'!H13, Participation!H13, 'Assurance Vie'!H13)=0, "", SUM('Livret Jeune'!H13, 'Livret A'!H13, 'Trade Republique'!H13, Participation!H13, 'Assurance Vie'!H13)) | I13: =IF(COUNTA('Livret Jeune'!I13, 'Livret A'!I13, 'Trade Republique'!I13, Participation!I13, 'Assurance Vie'!I13)=0, "", SUM('Livret Jeune'!I13, 'Livret A'!I13, 'Trade Republique'!I13, Participation!I13, 'Assurance Vie'!I13)) | ... M13: =IF(COUNTA('Livret Jeune'!M13, 'Livret A'!M13, 'Trade Republique'!M13, Participation!M13, 'Assurance Vie'!M13)=0, "", SUM('Livret Jeune'!M13, 'Livret A'!M13, 'Trade Republique'!M13, Participation!M13, 'Assurance Vie'!M13)) | N13: =SUM(B13:M13) -> 0
A14: 2033 | B14: =IF(COUNTA('Livret Jeune'!B14, 'Livret A'!B14, 'Trade Republique'!B14, Participation!B14, 'Assurance Vie'!B14)=0, "", SUM('Livret Jeune'!B14, 'Livret A'!B14, 'Trade Republique'!B14, Participation!B14, 'Assurance Vie'!B14)) | C14: =IF(COUNTA('Livret Jeune'!C14, 'Livret A'!C14, 'Trade Republique'!C14, Participation!C14, 'Assurance Vie'!C14)=0, "", SUM('Livret Jeune'!C14, 'Livret A'!C14, 'Trade Republique'!C14, Participation!C14, 'Assurance Vie'!C14)) | D14: =IF(COUNTA('Livret Jeune'!D14, 'Livret A'!D14, 'Trade Republique'!D14, Participation!D14, 'Assurance Vie'!D14)=0, "", SUM('Livret Jeune'!D14, 'Livret A'!D14, 'Trade Republique'!D14, Participation!D14, 'Assurance Vie'!D14)) | E14: =IF(COUNTA('Livret Jeune'!E14, 'Livret A'!E14, 'Trade Republique'!E14, Participation!E14, 'Assurance Vie'!E14)=0, "", SUM('Livret Jeune'!E14, 'Livret A'!E14, 'Trade Republique'!E14, Participation!E14, 'Assurance Vie'!E14)) | F14: =IF(COUNTA('Livret Jeune'!F14, 'Livret A'!F14, 'Trade Republique'!F14, Participation!F14, 'Assurance Vie'!F14)=0, "", SUM('Livret Jeune'!F14, 'Livret A'!F14, 'Trade Republique'!F14, Participation!F14, 'Assurance Vie'!F14)) | G14: =IF(COUNTA('Livret Jeune'!G14, 'Livret A'!G14, 'Trade Republique'!G14, Participation!G14, 'Assurance Vie'!G14)=0, "", SUM('Livret Jeune'!G14, 'Livret A'!G14, 'Trade Republique'!G14, Participation!G14, 'Assurance Vie'!G14)) | H14: =IF(COUNTA('Livret Jeune'!H14, 'Livret A'!H14, 'Trade Republique'!H14, Participation!H14, 'Assurance Vie'!H14)=0, "", SUM('Livret Jeune'!H14, 'Livret A'!H14, 'Trade Republique'!H14, Participation!H14, 'Assurance Vie'!H14)) | I14: =IF(COUNTA('Livret Jeune'!I14, 'Livret A'!I14, 'Trade Republique'!I14, Participation!I14, 'Assurance Vie'!I14)=0, "", SUM('Livret Jeune'!I14, 'Livret A'!I14, 'Trade Republique'!I14, Participation!I14, 'Assurance Vie'!I14)) | ... M14: =IF(COUNTA('Livret Jeune'!M14, 'Livret A'!M14, 'Trade Republique'!M14, Participation!M14, 'Assurance Vie'!M14)=0, "", SUM('Livret Jeune'!M14, 'Livret A'!M14, 'Trade Republique'!M14, Participation!M14, 'Assurance Vie'!M14)) | N14: =SUM(B14:M14) -> 0
A15: 2034 | B15: =IF(COUNTA('Livret Jeune'!B15, 'Livret A'!B15, 'Trade Republique'!B15, Participation!B15, 'Assurance Vie'!B15)=0, "", SUM('Livret Jeune'!B15, 'Livret A'!B15, 'Trade Republique'!B15, Participation!B15, 'Assurance Vie'!B15)) | C15: =IF(COUNTA('Livret Jeune'!C15, 'Livret A'!C15, 'Trade Republique'!C15, Participation!C15, 'Assurance Vie'!C15)=0, "", SUM('Livret Jeune'!C15, 'Livret A'!C15, 'Trade Republique'!C15, Participation!C15, 'Assurance Vie'!C15)) | D15: =IF(COUNTA('Livret Jeune'!D15, 'Livret A'!D15, 'Trade Republique'!D15, Participation!D15, 'Assurance Vie'!D15)=0, "", SUM('Livret Jeune'!D15, 'Livret A'!D15, 'Trade Republique'!D15, Participation!D15, 'Assurance Vie'!D15)) | E15: =IF(COUNTA('Livret Jeune'!E15, 'Livret A'!E15, 'Trade Republique'!E15, Participation!E15, 'Assurance Vie'!E15)=0, "", SUM('Livret Jeune'!E15, 'Livret A'!E15, 'Trade Republique'!E15, Participation!E15, 'Assurance Vie'!E15)) | F15: =IF(COUNTA('Livret Jeune'!F15, 'Livret A'!F15, 'Trade Republique'!F15, Participation!F15, 'Assurance Vie'!F15)=0, "", SUM('Livret Jeune'!F15, 'Livret A'!F15, 'Trade Republique'!F15, Participation!F15, 'Assurance Vie'!F15)) | G15: =IF(COUNTA('Livret Jeune'!G15, 'Livret A'!G15, 'Trade Republique'!G15, Participation!G15, 'Assurance Vie'!G15)=0, "", SUM('Livret Jeune'!G15, 'Livret A'!G15, 'Trade Republique'!G15, Participation!G15, 'Assurance Vie'!G15)) | H15: =IF(COUNTA('Livret Jeune'!H15, 'Livret A'!H15, 'Trade Republique'!H15, Participation!H15, 'Assurance Vie'!H15)=0, "", SUM('Livret Jeune'!H15, 'Livret A'!H15, 'Trade Republique'!H15, Participation!H15, 'Assurance Vie'!H15)) | I15: =IF(COUNTA('Livret Jeune'!I15, 'Livret A'!I15, 'Trade Republique'!I15, Participation!I15, 'Assurance Vie'!I15)=0, "", SUM('Livret Jeune'!I15, 'Livret A'!I15, 'Trade Republique'!I15, Participation!I15, 'Assurance Vie'!I15)) | ... M15: =IF(COUNTA('Livret Jeune'!M15, 'Livret A'!M15, 'Trade Republique'!M15, Participation!M15, 'Assurance Vie'!M15)=0, "", SUM('Livret Jeune'!M15, 'Livret A'!M15, 'Trade Republique'!M15, Participation!M15, 'Assurance Vie'!M15)) | N15: =SUM(B15:M15) -> 0
A16: 2035 | B16: =IF(COUNTA('Livret Jeune'!B16, 'Livret A'!B16, 'Trade Republique'!B16, Participation!B16, 'Assurance Vie'!B16)=0, "", SUM('Livret Jeune'!B16, 'Livret A'!B16, 'Trade Republique'!B16, Participation!B16, 'Assurance Vie'!B16)) | C16: =IF(COUNTA('Livret Jeune'!C16, 'Livret A'!C16, 'Trade Republique'!C16, Participation!C16, 'Assurance Vie'!C16)=0, "", SUM('Livret Jeune'!C16, 'Livret A'!C16, 'Trade Republique'!C16, Participation!C16, 'Assurance Vie'!C16)) | D16: =IF(COUNTA('Livret Jeune'!D16, 'Livret A'!D16, 'Trade Republique'!D16, Participation!D16, 'Assurance Vie'!D16)=0, "", SUM('Livret Jeune'!D16, 'Livret A'!D16, 'Trade Republique'!D16, Participation!D16, 'Assurance Vie'!D16)) | E16: =IF(COUNTA('Livret Jeune'!E16, 'Livret A'!E16, 'Trade Republique'!E16, Participation!E16, 'Assurance Vie'!E16)=0, "", SUM('Livret Jeune'!E16, 'Livret A'!E16, 'Trade Republique'!E16, Participation!E16, 'Assurance Vie'!E16)) | F16: =IF(COUNTA('Livret Jeune'!F16, 'Livret A'!F16, 'Trade Republique'!F16, Participation!F16, 'Assurance Vie'!F16)=0, "", SUM('Livret Jeune'!F16, 'Livret A'!F16, 'Trade Republique'!F16, Participation!F16, 'Assurance Vie'!F16)) | G16: =IF(COUNTA('Livret Jeune'!G16, 'Livret A'!G16, 'Trade Republique'!G16, Participation!G16, 'Assurance Vie'!G16)=0, "", SUM('Livret Jeune'!G16, 'Livret A'!G16, 'Trade Republique'!G16, Participation!G16, 'Assurance Vie'!G16)) | H16: =IF(COUNTA('Livret Jeune'!H16, 'Livret A'!H16, 'Trade Republique'!H16, Participation!H16, 'Assurance Vie'!H16)=0, "", SUM('Livret Jeune'!H16, 'Livret A'!H16, 'Trade Republique'!H16, Participation!H16, 'Assurance Vie'!H16)) | I16: =IF(COUNTA('Livret Jeune'!I16, 'Livret A'!I16, 'Trade Republique'!I16, Participation!I16, 'Assurance Vie'!I16)=0, "", SUM('Livret Jeune'!I16, 'Livret A'!I16, 'Trade Republique'!I16, Participation!I16, 'Assurance Vie'!I16)) | ... M16: =IF(COUNTA('Livret Jeune'!M16, 'Livret A'!M16, 'Trade Republique'!M16, Participation!M16, 'Assurance Vie'!M16)=0, "", SUM('Livret Jeune'!M16, 'Livret A'!M16, 'Trade Republique'!M16, Participation!M16, 'Assurance Vie'!M16)) | N16: =SUM(B16:M16) -> 0
A17: 2036 | B17: =IF(COUNTA('Livret Jeune'!B17, 'Livret A'!B17, 'Trade Republique'!B17, Participation!B17, 'Assurance Vie'!B17)=0, "", SUM('Livret Jeune'!B17, 'Livret A'!B17, 'Trade Republique'!B17, Participation!B17, 'Assurance Vie'!B17)) | C17: =IF(COUNTA('Livret Jeune'!C17, 'Livret A'!C17, 'Trade Republique'!C17, Participation!C17, 'Assurance Vie'!C17)=0, "", SUM('Livret Jeune'!C17, 'Livret A'!C17, 'Trade Republique'!C17, Participation!C17, 'Assurance Vie'!C17)) | D17: =IF(COUNTA('Livret Jeune'!D17, 'Livret A'!D17, 'Trade Republique'!D17, Participation!D17, 'Assurance Vie'!D17)=0, "", SUM('Livret Jeune'!D17, 'Livret A'!D17, 'Trade Republique'!D17, Participation!D17, 'Assurance Vie'!D17)) | E17: =IF(COUNTA('Livret Jeune'!E17, 'Livret A'!E17, 'Trade Republique'!E17, Participation!E17, 'Assurance Vie'!E17)=0, "", SUM('Livret Jeune'!E17, 'Livret A'!E17, 'Trade Republique'!E17, Participation!E17, 'Assurance Vie'!E17)) | F17: =IF(COUNTA('Livret Jeune'!F17, 'Livret A'!F17, 'Trade Republique'!F17, Participation!F17, 'Assurance Vie'!F17)=0, "", SUM('Livret Jeune'!F17, 'Livret A'!F17, 'Trade Republique'!F17, Participation!F17, 'Assurance Vie'!F17)) | G17: =IF(COUNTA('Livret Jeune'!G17, 'Livret A'!G17, 'Trade Republique'!G17, Participation!G17, 'Assurance Vie'!G17)=0, "", SUM('Livret Jeune'!G17, 'Livret A'!G17, 'Trade Republique'!G17, Participation!G17, 'Assurance Vie'!G17)) | H17: =IF(COUNTA('Livret Jeune'!H17, 'Livret A'!H17, 'Trade Republique'!H17, Participation!H17, 'Assurance Vie'!H17)=0, "", SUM('Livret Jeune'!H17, 'Livret A'!H17, 'Trade Republique'!H17, Participation!H17, 'Assurance Vie'!H17)) | I17: =IF(COUNTA('Livret Jeune'!I17, 'Livret A'!I17, 'Trade Republique'!I17, Participation!I17, 'Assurance Vie'!I17)=0, "", SUM('Livret Jeune'!I17, 'Livret A'!I17, 'Trade Republique'!I17, Participation!I17, 'Assurance Vie'!I17)) | ... M17: =IF(COUNTA('Livret Jeune'!M17, 'Livret A'!M17, 'Trade Republique'!M17, Participation!M17, 'Assurance Vie'!M17)=0, "", SUM('Livret Jeune'!M17, 'Livret A'!M17, 'Trade Republique'!M17, Participation!M17, 'Assurance Vie'!M17)) | N17: =SUM(B17:M17) -> 0
A18: 2037 | B18: =IF(COUNTA('Livret Jeune'!B18, 'Livret A'!B18, 'Trade Republique'!B18, Participation!B18, 'Assurance Vie'!B18)=0, "", SUM('Livret Jeune'!B18, 'Livret A'!B18, 'Trade Republique'!B18, Participation!B18, 'Assurance Vie'!B18)) | C18: =IF(COUNTA('Livret Jeune'!C18, 'Livret A'!C18, 'Trade Republique'!C18, Participation!C18, 'Assurance Vie'!C18)=0, "", SUM('Livret Jeune'!C18, 'Livret A'!C18, 'Trade Republique'!C18, Participation!C18, 'Assurance Vie'!C18)) | D18: =IF(COUNTA('Livret Jeune'!D18, 'Livret A'!D18, 'Trade Republique'!D18, Participation!D18, 'Assurance Vie'!D18)=0, "", SUM('Livret Jeune'!D18, 'Livret A'!D18, 'Trade Republique'!D18, Participation!D18, 'Assurance Vie'!D18)) | E18: =IF(COUNTA('Livret Jeune'!E18, 'Livret A'!E18, 'Trade Republique'!E18, Participation!E18, 'Assurance Vie'!E18)=0, "", SUM('Livret Jeune'!E18, 'Livret A'!E18, 'Trade Republique'!E18, Participation!E18, 'Assurance Vie'!E18)) | F18: =IF(COUNTA('Livret Jeune'!F18, 'Livret A'!F18, 'Trade Republique'!F18, Participation!F18, 'Assurance Vie'!F18)=0, "", SUM('Livret Jeune'!F18, 'Livret A'!F18, 'Trade Republique'!F18, Participation!F18, 'Assurance Vie'!F18)) | G18: =IF(COUNTA('Livret Jeune'!G18, 'Livret A'!G18, 'Trade Republique'!G18, Participation!G18, 'Assurance Vie'!G18)=0, "", SUM('Livret Jeune'!G18, 'Livret A'!G18, 'Trade Republique'!G18, Participation!G18, 'Assurance Vie'!G18)) | H18: =IF(COUNTA('Livret Jeune'!H18, 'Livret A'!H18, 'Trade Republique'!H18, Participation!H18, 'Assurance Vie'!H18)=0, "", SUM('Livret Jeune'!H18, 'Livret A'!H18, 'Trade Republique'!H18, Participation!H18, 'Assurance Vie'!H18)) | I18: =IF(COUNTA('Livret Jeune'!I18, 'Livret A'!I18, 'Trade Republique'!I18, Participation!I18, 'Assurance Vie'!I18)=0, "", SUM('Livret Jeune'!I18, 'Livret A'!I18, 'Trade Republique'!I18, Participation!I18, 'Assurance Vie'!I18)) | ... M18: =IF(COUNTA('Livret Jeune'!M18, 'Livret A'!M18, 'Trade Republique'!M18, Participation!M18, 'Assurance Vie'!M18)=0, "", SUM('Livret Jeune'!M18, 'Livret A'!M18, 'Trade Republique'!M18, Participation!M18, 'Assurance Vie'!M18)) | N18: =SUM(B18:M18) -> 0
... A24: 2043 | B24: =IF(COUNTA('Livret Jeune'!B24, 'Livret A'!B24, 'Trade Republique'!B24, Participation!B24, 'Assurance Vie'!B24)=0, "", SUM('Livret Jeune'!B24, 'Livret A'!B24, 'Trade Republique'!B24, Participation!B24, 'Assurance Vie'!B24)) | C24: =IF(COUNTA('Livret Jeune'!C24, 'Livret A'!C24, 'Trade Republique'!C24, Participation!C24, 'Assurance Vie'!C24)=0, "", SUM('Livret Jeune'!C24, 'Livret A'!C24, 'Trade Republique'!C24, Participation!C24, 'Assurance Vie'!C24)) | D24: =IF(COUNTA('Livret Jeune'!D24, 'Livret A'!D24, 'Trade Republique'!D24, Participation!D24, 'Assurance Vie'!D24)=0, "", SUM('Livret Jeune'!D24, 'Livret A'!D24, 'Trade Republique'!D24, Participation!D24, 'Assurance Vie'!D24)) | E24: =IF(COUNTA('Livret Jeune'!E24, 'Livret A'!E24, 'Trade Republique'!E24, Participation!E24, 'Assurance Vie'!E24)=0, "", SUM('Livret Jeune'!E24, 'Livret A'!E24, 'Trade Republique'!E24, Participation!E24, 'Assurance Vie'!E24)) | F24: =IF(COUNTA('Livret Jeune'!F24, 'Livret A'!F24, 'Trade Republique'!F24, Participation!F24, 'Assurance Vie'!F24)=0, "", SUM('Livret Jeune'!F24, 'Livret A'!F24, 'Trade Republique'!F24, Participation!F24, 'Assurance Vie'!F24)) | G24: =IF(COUNTA('Livret Jeune'!G24, 'Livret A'!G24, 'Trade Republique'!G24, Participation!G24, 'Assurance Vie'!G24)=0, "", SUM('Livret Jeune'!G24, 'Livret A'!G24, 'Trade Republique'!G24, Participation!G24, 'Assurance Vie'!G24)) | H24: =IF(COUNTA('Livret Jeune'!H24, 'Livret A'!H24, 'Trade Republique'!H24, Participation!H24, 'Assurance Vie'!H24)=0, "", SUM('Livret Jeune'!H24, 'Livret A'!H24, 'Trade Republique'!H24, Participation!H24, 'Assurance Vie'!H24)) | I24: =IF(COUNTA('Livret Jeune'!I24, 'Livret A'!I24, 'Trade Republique'!I24, Participation!I24, 'Assurance Vie'!I24)=0, "", SUM('Livret Jeune'!I24, 'Livret A'!I24, 'Trade Republique'!I24, Participation!I24, 'Assurance Vie'!I24)) | ... M24: =IF(COUNTA('Livret Jeune'!M24, 'Livret A'!M24, 'Trade Republique'!M24, Participation!M24, 'Assurance Vie'!M24)=0, "", SUM('Livret Jeune'!M24, 'Livret A'!M24, 'Trade Republique'!M24, Participation!M24, 'Assurance Vie'!M24)) | N24: =SUM(B24:M24) -> 0
A27: % Salaire
A28: Année | B28: Janvier | C28: Février | D28: Mars | E28: Avril | F28: Mai | G28: Juin | H28: Juillet | I28: Aout | J28: Septembre | K28: Octobre | L28: Novembre | M28: Décembre | N28: Moyenne si épargne | O28: Moyenne
A29: 2024 | B29: =IF(Salaire!B5>0,B5/Salaire!B5,"") | C29: =IF(Salaire!C5>0,C5/Salaire!C5,"") | D29: =IF(Salaire!D5>0,D5/Salaire!D5,"") | E29: =IF(Salaire!E5>0,E5/Salaire!E5,"") | F29: =IF(Salaire!F5>0,F5/Salaire!F5,"") | G29: =IF(Salaire!G5>0,G5/Salaire!G5,"") | H29: =IF(Salaire!H5>0,H5/Salaire!H5,"") | I29: =IF(Salaire!I5>0,I5/Salaire!I5,"") | ... M29: =IF(Salaire!M5>0,M5/Salaire!M5,"") | N29: =IFERROR(AVERAGEIF(B29:M29,">0",B29:M29),"") | O29: =IFERROR(AVERAGE(B29:M29),"")
A30: 2025 | B30: =IF(Salaire!B6>0,B6/Salaire!B6,"") | C30: =IF(Salaire!C6>0,C6/Salaire!C6,"") | D30: =IF(Salaire!D6>0,D6/Salaire!D6,"") | E30: =IF(Salaire!E6>0,E6/Salaire!E6,"") | F30: =IF(Salaire!F6>0,F6/Salaire!F6,"") | G30: =IF(Salaire!G6>0,G6/Salaire!G6,"") | H30: =IF(Salaire!H6>0,H6/Salaire!H6,"") | I30: =IF(Salaire!I6>0,I6/Salaire!I6,"") | ... M30: =IF(Salaire!M6>0,M6/Salaire!M6,"") | N30: =IFERROR(AVERAGEIF(B30:M30,">0",B30:M30),"") | O30: =IFERROR(AVERAGE(B30:M30),"")
A31: 2026 | B31: =IF(Salaire!B7>0,B7/Salaire!B7,"") | C31: =IF(Salaire!C7>0,C7/Salaire!C7,"") | D31: =IF(Salaire!D7>0,D7/Salaire!D7,"") | E31: =IF(Salaire!E7>0,E7/Salaire!E7,"") | F31: =IF(Salaire!F7>0,F7/Salaire!F7,"") | G31: =IF(Salaire!G7>0,G7/Salaire!G7,"") | H31: =IF(Salaire!H7>0,H7/Salaire!H7,"") | I31: =IF(Salaire!I7>0,I7/Salaire!I7,"") | ... M31: =IF(Salaire!M7>0,M7/Salaire!M7,"") | N31: =IFERROR(AVERAGEIF(B31:M31,">0",B31:M31),"") | O31: =IFERROR(AVERAGE(B31:M31),"")
A32: 2027 | B32: =IF(Salaire!B8>0,B8/Salaire!B8,"") | C32: =IF(Salaire!C8>0,C8/Salaire!C8,"") | D32: =IF(Salaire!D8>0,D8/Salaire!D8,"") | E32: =IF(Salaire!E8>0,E8/Salaire!E8,"") | F32: =IF(Salaire!F8>0,F8/Salaire!F8,"") | G32: =IF(Salaire!G8>0,G8/Salaire!G8,"") | H32: =IF(Salaire!H8>0,H8/Salaire!H8,"") | I32: =IF(Salaire!I8>0,I8/Salaire!I8,"") | ... M32: =IF(Salaire!M8>0,M8/Salaire!M8,"") | N32: =IFERROR(AVERAGEIF(B32:M32,">0",B32:M32),"") | O32: =IFERROR(AVERAGE(B32:M32),"")
A33: 2028 | B33: =IF(Salaire!B9>0,B9/Salaire!B9,"") | C33: =IF(Salaire!C9>0,C9/Salaire!C9,"") | D33: =IF(Salaire!D9>0,D9/Salaire!D9,"") | E33: =IF(Salaire!E9>0,E9/Salaire!E9,"") | F33: =IF(Salaire!F9>0,F9/Salaire!F9,"") | G33: =IF(Salaire!G9>0,G9/Salaire!G9,"") | H33: =IF(Salaire!H9>0,H9/Salaire!H9,"") | I33: =IF(Salaire!I9>0,I9/Salaire!I9,"") | ... M33: =IF(Salaire!M9>0,M9/Salaire!M9,"") | N33: =IFERROR(AVERAGEIF(B33:M33,">0",B33:M33),"") | O33: =IFERROR(AVERAGE(B33:M33),"")
A34: 2029 | B34: =IF(Salaire!B10>0,B10/Salaire!B10,"") | C34: =IF(Salaire!C10>0,C10/Salaire!C10,"") | D34: =IF(Salaire!D10>0,D10/Salaire!D10,"") | E34: =IF(Salaire!E10>0,E10/Salaire!E10,"") | F34: =IF(Salaire!F10>0,F10/Salaire!F10,"") | G34: =IF(Salaire!G10>0,G10/Salaire!G10,"") | H34: =IF(Salaire!H10>0,H10/Salaire!H10,"") | I34: =IF(Salaire!I10>0,I10/Salaire!I10,"") | ... M34: =IF(Salaire!M10>0,M10/Salaire!M10,"") | N34: =IFERROR(AVERAGEIF(B34:M34,">0",B34:M34),"") | O34: =IFERROR(AVERAGE(B34:M34),"")
A35: 2030 | B35: =IF(Salaire!B11>0,B11/Salaire!B11,"") | C35: =IF(Salaire!C11>0,C11/Salaire!C11,"") | D35: =IF(Salaire!D11>0,D11/Salaire!D11,"") | E35: =IF(Salaire!E11>0,E11/Salaire!E11,"") | F35: =IF(Salaire!F11>0,F11/Salaire!F11,"") | G35: =IF(Salaire!G11>0,G11/Salaire!G11,"") | H35: =IF(Salaire!H11>0,H11/Salaire!H11,"") | I35: =IF(Salaire!I11>0,I11/Salaire!I11,"") | ... M35: =IF(Salaire!M11>0,M11/Salaire!M11,"") | N35: =IFERROR(AVERAGEIF(B35:M35,">0",B35:M35),"") | O35: =IFERROR(AVERAGE(B35:M35),"")
A36: 2031 | B36: =IF(Salaire!B12>0,B12/Salaire!B12,"") | C36: =IF(Salaire!C12>0,C12/Salaire!C12,"") | D36: =IF(Salaire!D12>0,D12/Salaire!D12,"") | E36: =IF(Salaire!E12>0,E12/Salaire!E12,"") | F36: =IF(Salaire!F12>0,F12/Salaire!F12,"") | G36: =IF(Salaire!G12>0,G12/Salaire!G12,"") | H36: =IF(Salaire!H12>0,H12/Salaire!H12,"") | I36: =IF(Salaire!I12>0,I12/Salaire!I12,"") | ... M36: =IF(Salaire!M12>0,M12/Salaire!M12,"") | N36: =IFERROR(AVERAGEIF(B36:M36,">0",B36:M36),"") | O36: =IFERROR(AVERAGE(B36:M36),"")
A37: 2032 | B37: =IF(Salaire!B13>0,B13/Salaire!B13,"") | C37: =IF(Salaire!C13>0,C13/Salaire!C13,"") | D37: =IF(Salaire!D13>0,D13/Salaire!D13,"") | E37: =IF(Salaire!E13>0,E13/Salaire!E13,"") | F37: =IF(Salaire!F13>0,F13/Salaire!F13,"") | G37: =IF(Salaire!G13>0,G13/Salaire!G13,"") | H37: =IF(Salaire!H13>0,H13/Salaire!H13,"") | I37: =IF(Salaire!I13>0,I13/Salaire!I13,"") | ... M37: =IF(Salaire!M13>0,M13/Salaire!M13,"") | N37: =IFERROR(AVERAGEIF(B37:M37,">0",B37:M37),"") | O37: =IFERROR(AVERAGE(B37:M37),"")
A38: 2033 | B38: =IF(Salaire!B14>0,B14/Salaire!B14,"") | C38: =IF(Salaire!C14>0,C14/Salaire!C14,"") | D38: =IF(Salaire!D14>0,D14/Salaire!D14,"") | E38: =IF(Salaire!E14>0,E14/Salaire!E14,"") | F38: =IF(Salaire!F14>0,F14/Salaire!F14,"") | G38: =IF(Salaire!G14>0,G14/Salaire!G14,"") | H38: =IF(Salaire!H14>0,H14/Salaire!H14,"") | I38: =IF(Salaire!I14>0,I14/Salaire!I14,"") | ... M38: =IF(Salaire!M14>0,M14/Salaire!M14,"") | N38: =IFERROR(AVERAGEIF(B38:M38,">0",B38:M38),"") | O38: =IFERROR(AVERAGE(B38:M38),"")
A39: 2034 | B39: =IF(Salaire!B15>0,B15/Salaire!B15,"") | C39: =IF(Salaire!C15>0,C15/Salaire!C15,"") | D39: =IF(Salaire!D15>0,D15/Salaire!D15,"") | E39: =IF(Salaire!E15>0,E15/Salaire!E15,"") | F39: =IF(Salaire!F15>0,F15/Salaire!F15,"") | G39: =IF(Salaire!G15>0,G15/Salaire!G15,"") | H39: =IF(Salaire!H15>0,H15/Salaire!H15,"") | I39: =IF(Salaire!I15>0,I15/Salaire!I15,"") | ... M39: =IF(Salaire!M15>0,M15/Salaire!M15,"") | N39: =IFERROR(AVERAGEIF(B39:M39,">0",B39:M39),"") | O39: =IFERROR(AVERAGE(B39:M39),"")
A40: 2035 | B40: =IF(Salaire!B16>0,B16/Salaire!B16,"") | C40: =IF(Salaire!C16>0,C16/Salaire!C16,"") | D40: =IF(Salaire!D16>0,D16/Salaire!D16,"") | E40: =IF(Salaire!E16>0,E16/Salaire!E16,"") | F40: =IF(Salaire!F16>0,F16/Salaire!F16,"") | G40: =IF(Salaire!G16>0,G16/Salaire!G16,"") | H40: =IF(Salaire!H16>0,H16/Salaire!H16,"") | I40: =IF(Salaire!I16>0,I16/Salaire!I16,"") | ... M40: =IF(Salaire!M16>0,M16/Salaire!M16,"") | N40: =IFERROR(AVERAGEIF(B40:M40,">0",B40:M40),"") | O40: =IFERROR(AVERAGE(B40:M40),"")
... A48: 2043 | B48: =IF(Salaire!B24>0,B24/Salaire!B24,"") | C48: =IF(Salaire!C24>0,C24/Salaire!C24,"") | D48: =IF(Salaire!D24>0,D24/Salaire!D24,"") | E48: =IF(Salaire!E24>0,E24/Salaire!E24,"") | F48: =IF(Salaire!F24>0,F24/Salaire!F24,"") | G48: =IF(Salaire!G24>0,G24/Salaire!G24,"") | H48: =IF(Salaire!H24>0,H24/Salaire!H24,"") | I48: =IF(Salaire!I24>0,I24/Salaire!I24,"") | ... M48: =IF(Salaire!M24>0,M24/Salaire!M24,"") | N48: =IFERROR(AVERAGEIF(B48:M48,">0",B48:M48),"") | O48: =IFERROR(AVERAGE(B48:M48),"")
A51: Épargne
A52: Année | B52: Janvier | C52: Février | D52: Mars | E52: Avril | F52: Mai | G52: Juin | H52: Juillet | I52: Aout | J52: Septembre | K52: Octobre | L52: Novembre | M52: Décembre | N52: Total Sur l'année
A53: 2024 | B53: =SUM('Livret Jeune'!B5,'Livret A'!B5,'Trade Republique'!B103,'Trade Republique'!B52,'Trade Republique'!B128,Participation!B5,'Assurance Vie'!B5) -> 0 | C53: =SUM('Livret Jeune'!C5,'Livret A'!C5,'Trade Republique'!C103,'Trade Republique'!C52,'Trade Republique'!C128,Participation!C5,'Assurance Vie'!C5) -> 0 | D53: =SUM('Livret Jeune'!D5,'Livret A'!D5,'Trade Republique'!D103,'Trade Republique'!D52,'Trade Republique'!D128,Participation!D5,'Assurance Vie'!D5) -> 0 | E53: =SUM('Livret Jeune'!E5,'Livret A'!E5,'Trade Republique'!E103,'Trade Republique'!E52,'Trade Republique'!E128,Participation!E5,'Assurance Vie'!E5) -> 0 | F53: =SUM('Livret Jeune'!F5,'Livret A'!F5,'Trade Republique'!F103,'Trade Republique'!F52,'Trade Republique'!F128,Participation!F5,'Assurance Vie'!F5) -> 0 | G53: =SUM('Livret Jeune'!G5,'Livret A'!G5,'Trade Republique'!G103,'Trade Republique'!G52,'Trade Republique'!G128,Participation!G5,'Assurance Vie'!G5) -> 0 | H53: =SUM('Livret Jeune'!H5,'Livret A'!H5,'Trade Republique'!H103,'Trade Republique'!H52,'Trade Republique'!H128,Participation!H5,'Assurance Vie'!H5) -> 0 | I53: =SUM('Livret Jeune'!I5,'Livret A'!I5,'Trade Republique'!I103,'Trade Republique'!I52,'Trade Republique'!I128,Participation!I5,'Assurance Vie'!I5) -> 0 | ... M53: =SUM('Livret Jeune'!M5,'Livret A'!M5,'Trade Republique'!M103,'Trade Republique'!M52,'Trade Republique'!M128,Participation!M5,'Assurance Vie'!M5) -> 0 | N53: =IFERROR(AVERAGEIF(B53:M53,">0",B53:M53),"")
A54: 2025 | B54: =SUM('Livret Jeune'!B6,'Livret A'!B6,'Trade Republique'!B104,'Trade Republique'!B53,'Trade Republique'!B129,Participation!B6,'Assurance Vie'!B6) -> 0 | C54: =SUM('Livret Jeune'!C6,'Livret A'!C6,'Trade Republique'!C104,'Trade Republique'!C53,'Trade Republique'!C129,Participation!C6,'Assurance Vie'!C6) -> 0 | D54: =SUM('Livret Jeune'!D6,'Livret A'!D6,'Trade Republique'!D104,'Trade Republique'!D53,'Trade Republique'!D129,Participation!D6,'Assurance Vie'!D6) -> 0 | E54: =SUM('Livret Jeune'!E6,'Livret A'!E6,'Trade Republique'!E104,'Trade Republique'!E53,'Trade Republique'!E129,Participation!E6,'Assurance Vie'!E6) -> 0 | F54: =SUM('Livret Jeune'!F6,'Livret A'!F6,'Trade Republique'!F104,'Trade Republique'!F53,'Trade Republique'!F129,Participation!F6,'Assurance Vie'!F6) -> 0 | G54: =SUM('Livret Jeune'!G6,'Livret A'!G6,'Trade Republique'!G104,'Trade Republique'!G53,'Trade Republique'!G129,Participation!G6,'Assurance Vie'!G6) -> 0 | H54: =SUM('Livret Jeune'!H6,'Livret A'!H6,'Trade Republique'!H104,'Trade Republique'!H53,'Trade Republique'!H129,Participation!H6,'Assurance Vie'!H6) -> 0 | I54: =SUM('Livret Jeune'!I6,'Livret A'!I6,'Trade Republique'!I104,'Trade Republique'!I53,'Trade Republique'!I129,Participation!I6,'Assurance Vie'!I6) -> 0 | ... M54: =SUM('Livret Jeune'!M6,'Livret A'!M6,'Trade Republique'!M104,'Trade Republique'!M53,'Trade Republique'!M129,Participation!M6,'Assurance Vie'!M6) -> 0 | N54: =IFERROR(AVERAGEIF(B54:M54,">0",B54:M54),"")
A55: 2026 | B55: =SUM('Livret Jeune'!B7,'Livret A'!B7,'Trade Republique'!B105,'Trade Republique'!B54,'Trade Republique'!B130,Participation!B7,'Assurance Vie'!B7) -> 0 | C55: =SUM('Livret Jeune'!C7,'Livret A'!C7,'Trade Republique'!C105,'Trade Republique'!C54,'Trade Republique'!C130,Participation!C7,'Assurance Vie'!C7) -> 0 | D55: =SUM('Livret Jeune'!D7,'Livret A'!D7,'Trade Republique'!D105,'Trade Republique'!D54,'Trade Republique'!D130,Participation!D7,'Assurance Vie'!D7) -> 0 | E55: =SUM('Livret Jeune'!E7,'Livret A'!E7,'Trade Republique'!E105,'Trade Republique'!E54,'Trade Republique'!E130,Participation!E7,'Assurance Vie'!E7) -> 0 | F55: =SUM('Livret Jeune'!F7,'Livret A'!F7,'Trade Republique'!F105,'Trade Republique'!F54,'Trade Republique'!F130,Participation!F7,'Assurance Vie'!F7) -> 0 | G55: =SUM('Livret Jeune'!G7,'Livret A'!G7,'Trade Republique'!G105,'Trade Republique'!G54,'Trade Republique'!G130,Participation!G7,'Assurance Vie'!G7) -> 0 | H55: =SUM('Livret Jeune'!H7,'Livret A'!H7,'Trade Republique'!H105,'Trade Republique'!H54,'Trade Republique'!H130,Participation!H7,'Assurance Vie'!H7) -> 0 | I55: =SUM('Livret Jeune'!I7,'Livret A'!I7,'Trade Republique'!I105,'Trade Republique'!I54,'Trade Republique'!I130,Participation!I7,'Assurance Vie'!I7) -> 0 | ... M55: =SUM('Livret Jeune'!M7,'Livret A'!M7,'Trade Republique'!M105,'Trade Republique'!M54,'Trade Republique'!M130,Participation!M7,'Assurance Vie'!M7) -> 0 | N55: =IFERROR(AVERAGEIF(B55:M55,">0",B55:M55),"")
A56: 2027 | B56: =SUM('Livret Jeune'!B8,'Livret A'!B8,'Trade Republique'!B106,'Trade Republique'!B55,'Trade Republique'!B131,Participation!B8,'Assurance Vie'!B8) -> 0 | C56: =SUM('Livret Jeune'!C8,'Livret A'!C8,'Trade Republique'!C106,'Trade Republique'!C55,'Trade Republique'!C131,Participation!C8,'Assurance Vie'!C8) -> 0 | D56: =SUM('Livret Jeune'!D8,'Livret A'!D8,'Trade Republique'!D106,'Trade Republique'!D55,'Trade Republique'!D131,Participation!D8,'Assurance Vie'!D8) -> 0 | E56: =SUM('Livret Jeune'!E8,'Livret A'!E8,'Trade Republique'!E106,'Trade Republique'!E55,'Trade Republique'!E131,Participation!E8,'Assurance Vie'!E8) -> 0 | F56: =SUM('Livret Jeune'!F8,'Livret A'!F8,'Trade Republique'!F106,'Trade Republique'!F55,'Trade Republique'!F131,Participation!F8,'Assurance Vie'!F8) -> 0 | G56: =SUM('Livret Jeune'!G8,'Livret A'!G8,'Trade Republique'!G106,'Trade Republique'!G55,'Trade Republique'!G131,Participation!G8,'Assurance Vie'!G8) -> 0 | H56: =SUM('Livret Jeune'!H8,'Livret A'!H8,'Trade Republique'!H106,'Trade Republique'!H55,'Trade Republique'!H131,Participation!H8,'Assurance Vie'!H8) -> 0 | I56: =SUM('Livret Jeune'!I8,'Livret A'!I8,'Trade Republique'!I106,'Trade Republique'!I55,'Trade Republique'!I131,Participation!I8,'Assurance Vie'!I8) -> 0 | ... M56: =SUM('Livret Jeune'!M8,'Livret A'!M8,'Trade Republique'!M106,'Trade Republique'!M55,'Trade Republique'!M131,Participation!M8,'Assurance Vie'!M8) -> 0 | N56: =IFERROR(AVERAGEIF(B56:M56,">0",B56:M56),"")
A57: 2028 | B57: =SUM('Livret Jeune'!B9,'Livret A'!B9,'Trade Republique'!B107,'Trade Republique'!B56,'Trade Republique'!B132,Participation!B9,'Assurance Vie'!B9) -> 0 | C57: =SUM('Livret Jeune'!C9,'Livret A'!C9,'Trade Republique'!C107,'Trade Republique'!C56,'Trade Republique'!C132,Participation!C9,'Assurance Vie'!C9) -> 0 | D57: =SUM('Livret Jeune'!D9,'Livret A'!D9,'Trade Republique'!D107,'Trade Republique'!D56,'Trade Republique'!D132,Participation!D9,'Assurance Vie'!D9) -> 0 | E57: =SUM('Livret Jeune'!E9,'Livret A'!E9,'Trade Republique'!E107,'Trade Republique'!E56,'Trade Republique'!E132,Participation!E9,'Assurance Vie'!E9) -> 0 | F57: =SUM('Livret Jeune'!F9,'Livret A'!F9,'Trade Republique'!F107,'Trade Republique'!F56,'Trade Republique'!F132,Participation!F9,'Assurance Vie'!F9) -> 0 | G57: =SUM('Livret Jeune'!G9,'Livret A'!G9,'Trade Republique'!G107,'Trade Republique'!G56,'Trade Republique'!G132,Participation!G9,'Assurance Vie'!G9) -> 0 | H57: =SUM('Livret Jeune'!H9,'Livret A'!H9,'Trade Republique'!H107,'Trade Republique'!H56,'Trade Republique'!H132,Participation!H9,'Assurance Vie'!H9) -> 0 | I57: =SUM('Livret Jeune'!I9,'Livret A'!I9,'Trade Republique'!I107,'Trade Republique'!I56,'Trade Republique'!I132,Participation!I9,'Assurance Vie'!I9) -> 0 | ... M57: =SUM('Livret Jeune'!M9,'Livret A'!M9,'Trade Republique'!M107,'Trade Republique'!M56,'Trade Republique'!M132,Participation!M9,'Assurance Vie'!M9) -> 0 | N57: =IFERROR(AVERAGEIF(B57:M57,">0",B57:M57),"")
...

Sheet Livret Jeune
B1: Livret Jeune | C1: Solde de départ | D1: 0 | F1: Solde actuel | G1: =D1+SUM(B5:N24) -> 0 | I1: Plafond | J1: 1600 | L1: Reste Avant planfond | M1: =J1-G1 -> 1600
C2: Date de départ | D2: 45543
A4: Année | B4: Janvier | C4: Février | D4: Mars | E4: Avril | F4: Mai | G4: Juin | H4: Juillet | I4: Aout | J4: Septembre | K4: Octobre | L4: Novembre | M4: Décembre | N4: Intéréts au 31 | O4: Total Sur l'année | Q4: =N5/(G1-N5) -> #DIV/0!
A5: 2024 | B5: 0 | C5: 0 | D5: 0 | E5: 0 | F5: 0 | G5: 0 | H5: 0 | I5: 0 | J5: 0 | K5: 0 | L5: 0 | M5: 0 | N5: 0 | O5: =SUM(B5:N5) -> 0
A6: 2025 | B6: 0 | C6: 0 | D6: 0 | E6: 0 | F6: 0 | G6: 0 | H6: 0 | I6: 0 | J6: 0 | K6: 0 | L6: 0 | M6: 0 | N6: 0 | O6: =SUM(B6:N6) -> 0
A7: 2026 | B7: 0 | C7: 0 | D7: 0 | E7: 0 | F7: 0 | G7: 0 | O7: =SUM(B7:N7) -> 0
A8: 2027 | O8: =SUM(B8:N8) -> 0
A9: 2028 | O9: =SUM(B9:N9) -> 0
A10: 2029 | O10: =SUM(B10:N10) -> 0
A11: 2030 | O11: =SUM(B11:N11) -> 0
A12: 2031 | O12: =SUM(B12:N12) -> 0
A13: 2032 | O13: =SUM(B13:N13) -> 0
A14: 2033 | O14: =SUM(B14:N14) -> 0
A15: 2034 | O15: =SUM(B15:N15) -> 0
A16: 2035 | O16: =SUM(B16:N16) -> 0
A17: 2036 | O17: =SUM(B17:N17) -> 0
A18: 2037 | O18: =SUM(B18:N18) -> 0
A19: 2038 | O19: =SUM(B19:N19) -> 0
... A24: 2043 | O24: =SUM(B24:N24) -> 0

Sheet Livret A
B1: Livret A | C1: Solde de départ | D1: 0 | F1: Solde actuel | G1: =D1+SUM(B5:N24) -> 0 | I1: Plafond | J1: 22950 | L1: Reste avant planfond | M1: =J1-G1 -> 22950
C2: Date de départ | D2: 45543
A4: Année | B4: Janvier | C4: Février | D4: Mars | E4: Avril | F4: Mai | G4: Juin | H4: Juillet | I4: Aout | J4: Septembre | K4: Octobre | L4: Novembre | M4: Décembre | N4: Intérêts au 31 Décembre | O4: Total Sur l'année | Q4: =N5/(G1-N5) -> #DIV/0!
A5: 2024 | B5: 0 | C5: 0 | D5: 0 | E5: 0 | F5: 0 | G5: 0 | H5: 0 | I5: 0 | J5: 0 | K5: 0 | L5: 0 | M5: 0 | N5: 0 | O5: =SUM(B5:N5) -> 0
A6: 2025 | B6: 0 | C6: 0 | D6: 0 | E6: 0 | F6: 0 | G6: 0 | H6: 0 | I6: 0 | J6: 0 | K6: 0 | L6: 0 | M6: 0 | N6: 0 | O6: =SUM(B6:N6) -> 0
A7: 2026 | B7: =630 -200 -430 -> 0 | C7: =630 -200 -430 -> 0 | D7: =630 -200 -430 -> 0 | E7: =630 -200 -430 -> 0 | F7: =630 -200 -430 -> 0 | G7: =630 -200 -430 -> 0 | O7: =SUM(B7:N7) -> 0
A8: 2027 | O8: =SUM(B8:N8) -> 0
A9: 2028 | O9: =SUM(B9:N9) -> 0
A10: 2029 | O10: =SUM(B10:N10) -> 0
A11: 2030 | O11: =SUM(B11:N11) -> 0
A12: 2031 | O12: =SUM(B12:N12) -> 0
A13: 2032 | O13: =SUM(B13:N13) -> 0
A14: 2033 | O14: =SUM(B14:N14) -> 0
A15: 2034 | O15: =SUM(B15:N15) -> 0
A16: 2035 | O16: =SUM(B16:N16) -> 0
A17: 2036 | O17: =SUM(B17:N17) -> 0
A18: 2037 | O18: =SUM(B18:N18) -> 0
A19: 2038 | O19: =SUM(B19:N19) -> 0
... A24: 2043 | O24: =SUM(B24:N24) -> 0

Sheet Trade Republique
B1: Trade Republique | C1: Solde de départ | D1: 0 | F1: Solde Actuel | G1: =LOOKUP(9^9,N52:N71)+N123+N172 -> 0 | I1: Evolution | J1: =ABS(G1-SUMIF(B5:M24,">=0"))/SUMIF(B5:M24,">=0") -> #DIV/0! | L1: Gain | M1: =-SUM(B5:M24) -> 0
C2: Date de départ | D2: 45543
A4: Année | B4: Janvier | C4: Février | D4: Mars | E4: Avril | F4: Mai | G4: Juin | H4: Juillet | I4: Aout | J4: Septembre | K4: Octobre | L4: Novembre | M4: Décembre | N4: Total Sur l'année
A5: 2024 | B5: 0 | C5: 0 | D5: 0 | E5: 0 | F5: 0 | G5: 0 | H5: 0 | I5: 0 | J5: 0 | K5: 0 | L5: 0 | M5: 0 | N5: =SUM(B5:M5) -> 0
A6: 2025 | B6: 0 | C6: 0 | D6: 0 | E6: 0 | F6: 0 | G6: 0 | H6: 0 | I6: 0 | J6: 0 | K6: 0 | L6: 0 | M6: 0 | N6: =SUM(B6:M6) -> 0
A7: 2026 | B7: 0 | C7: 0 | D7: 0 | E7: 0 | F7: 0 | G7: 0 | N7: =SUM(B7:M7) -> 0
A8: 2027 | N8: =SUM(B8:M8) -> 0
A9: 2028 | N9: =SUM(B9:M9) -> 0
A10: 2029 | N10: =SUM(B10:M10) -> 0
A11: 2030 | N11: =SUM(B11:M11) -> 0
A12: 2031 | N12: =SUM(B12:M12) -> 0
A13: 2032 | N13: =SUM(B13:M13) -> 0
A14: 2033 | N14: =SUM(B14:M14) -> 0
A15: 2034 | N15: =SUM(B15:M15) -> 0
A16: 2035 | N16: =SUM(B16:M16) -> 0
A17: 2036 | N17: =SUM(B17:M17) -> 0
A18: 2037 | N18: =SUM(B18:M18) -> 0
A19: 2038 | N19: =SUM(B19:M19) -> 0
... A24: 2043 | N24: =SUM(B24:M24) -> 0
B26: Bourse
A27: Année | B27: Janvier | C27: Février | D27: Mars | E27: Avril | F27: Mai | G27: Juin | H27: Juillet | I27: Aout | J27: Septembre | K27: Octobre | L27: Novembre | M27: Décembre | N27: Total Sur l'année
A28: 2024 | B28: 0 | C28: 0 | D28: 0 | E28: 0 | F28: 0 | G28: 0 | H28: 0 | I28: 0 | J28: 0 | K28: 0 | L28: 0 | M28: 0 | N28: =SUM(B28:M28) -> 0
A29: 2025 | B29: 0 | C29: 0 | D29: 0 | E29: 0 | F29: 0 | G29: 0 | H29: 0 | I29: 0 | J29: 0 | K29: 0 | L29: 0 | M29: 0 | N29: =SUM(B29:M29) -> 0
A30: 2026 | B30: 0 | C30: 0 | D30: 0 | E30: 0 | F30: 0 | G30: 0 | N30: =SUM(B30:M30) -> 0
A31: 2027 | N31: =SUM(B31:M31) -> 0
A32: 2028 | N32: =SUM(B32:M32) -> 0
A33: 2029 | N33: =SUM(B33:M33) -> 0
A34: 2030 | N34: =SUM(B34:M34) -> 0
A35: 2031 | N35: =SUM(B35:M35) -> 0
A36: 2032 | N36: =SUM(B36:M36) -> 0
A37: 2033 | N37: =SUM(B37:M37) -> 0
A38: 2034 | N38: =SUM(B38:M38) -> 0
A39: 2035 | N39: =SUM(B39:M39) -> 0
A40: 2036 | N40: =SUM(B40:M40) -> 0
A41: 2037 | N41: =SUM(B41:M41) -> 0
A42: 2038 | N42: =SUM(B42:M42) -> 0
... A47: 2043 | N47: =SUM(B47:M47) -> 0
B50: Compte | D50: Plafond | E50: 50000 | H50: Reste avant plafond | I50: =E50-LOOKUP(9^9,N52:N71) -> 50000
A51: Année | B51: Janvier | C51: Février | D51: Mars | E51: Avril | F51: Mai | G51: Juin | H51: Juillet | I51: Aout | J51: Septembre | K51: Octobre | L51: Novembre | M51: Décembre | N51: Total Sur l'année
A52: 2024 | B52: 0 | C52: =IF(C5="","",B52-C28-C128+C5+C78) -> 0 | D52: =IF(D5="","",C52-D28-D128+D5+D78) -> 0 | E52: =IF(E5="","",D52-E28-E128+E5+E78) -> 0 | F52: =IF(F5="","",E52-F28-F128+F5+F78) -> 0 | G52: =IF(G5="","",F52-G28-G128+G5+G78) -> 0 | H52: =IF(H5="","",G52-H28-H128+H5+H78) -> 0 | I52: =IF(I5="","",H52-I28-I128+I5+I78) -> 0 | J52: =IF(J5="","",I52-J28-J128+J5+J78) -> 0 | ... M52: =IF(M5="","",L52-M28-M128+M5+M78) -> 0 | N52: =IF(B52="","",LOOKUP(9^9,B52:M52)) -> 0
...

Sheet Participation
B1: Participation | C1: Solde de départ | D1: 0 | F1: Solde actuel | G1: =D1+SUM(B5:N24) -> 0 | I1: Évolution espérée /an | J1: 0.1093
C2: Date de départ | D2: 45856
A4: Année | B4: Janvier | C4: Février | D4: Mars | E4: Avril | F4: Mai | G4: Juin | H4: Juillet | I4: Aout | J4: Septembre | K4: Octobre | L4: Novembre | M4: Décembre | N4: Intérêts au 31 Décembre | O4: Total Sur l'année | P4: Date de l'épargne | Q4: Évolution Annuelle
A5: 2024 | B5: 0 | C5: 0 | D5: 0 | E5: 0 | F5: 0 | G5: 0 | H5: 0 | I5: 0 | J5: 0 | K5: 0 | L5: 0 | M5: 0 | N5: 0 | O5: =SUM(B5:M5) -> 0 | Q5: 0
A6: 2025 | B6: 0 | C6: 0 | D6: 0 | E6: 0 | F6: 0 | G6: 0 | H6: 0 | I6: 0 | J6: 0 | K6: 0 | L6: 0 | M6: 0 | N6: 0 | O6: =SUM(B6:M6) -> 0 | P6: 45897 | Q6: =N6/I6 -> #DIV/0!
A7: 2026 | B7: 0 | C7: 0 | D7: 0 | E7: 0 | F7: 0 | G7: 0 | O7: =SUM(B7:M7) -> 0
A8: 2027 | O8: =SUM(B8:M8) -> 0
A9: 2028 | O9: =SUM(B9:M9) -> 0
A10: 2029 | O10: =SUM(B10:M10) -> 0
A11: 2030 | O11: =SUM(B11:M11) -> 0
A12: 2031 | O12: =SUM(B12:M12) -> 0
A13: 2032 | O13: =SUM(B13:M13) -> 0
A14: 2033 | O14: =SUM(B14:M14) -> 0
A15: 2034 | O15: =SUM(B15:M15) -> 0
A16: 2035 | O16: =SUM(B16:M16) -> 0
A17: 2036 | O17: =SUM(B17:M17) -> 0
A18: 2037 | O18: =SUM(B18:M18) -> 0
A19: 2038 | O19: =SUM(B19:M19) -> 0
... A24: 2043 | O24: =SUM(B24:M24) -> 0

Sheet Assurance Vie
B1: Assurance vie | C1: Solde de départ | D1: 0 | F1: Solde actuel | G1: =LOOKUP(9^9,N28:N47) -> 0 | I1: Plafond | J1: 9999999999 | L1: Reste avant plafond | M1: =J1-G1 -> 9999999999 | O1: Évolution | P1: =(G1-G2)/G2 -> #DIV/0!
C2: Date de départ | D2: 45955 | F2: Solde actuel Prévu | G2: =D1+SUM(B5:N24) -> 0
A4: Année | B4: Janvier | C4: Février | D4: Mars | E4: Avril | F4: Mai | G4: Juin | H4: Juillet | I4: Aout | J4: Septembre | K4: Octobre | L4: Novembre | M4: Décembre | N4: Revalorisation au 31 Décembre | O4: Total Sur l'année | Q4: =N5/(G1-N5) -> #DIV/0!
A5: 2024 | B5: 0 | C5: 0 | D5: 0 | E5: 0 | F5: 0 | G5: 0 | H5: 0 | I5: 0 | J5: 0 | K5: 0 | L5: 0 | M5: 0 | N5: 0 | O5: =SUM(B5:M5) -> 0
A6: 2025 | B6: 0 | C6: 0 | D6: 0 | E6: 0 | F6: 0 | G6: 0 | H6: 0 | I6: 0 | J6: 0 | K6: 0 | L6: 0 | M6: 0 | N6: 0 | O6: =SUM(B6:M6) -> 0
A7: 2026 | B7: 0 | C7: 0 | D7: 0 | E7: 0 | F7: 0 | O7: =SUM(B7:M7) -> 0
A8: 2027 | O8: =SUM(B8:M8) -> 0
A9: 2028 | O9: =SUM(B9:M9) -> 0
A10: 2029 | O10: =SUM(B10:M10) -> 0
A11: 2030 | O11: =SUM(B11:M11) -> 0
A12: 2031 | O12: =SUM(B12:M12) -> 0
A13: 2032 | O13: =SUM(B13:M13) -> 0
A14: 2033 | O14: =SUM(B14:M14) -> 0
A15: 2034 | O15: =SUM(B15:M15) -> 0
A16: 2035 | O16: =SUM(B16:M16) -> 0
A17: 2036 | O17: =SUM(B17:M17) -> 0
A18: 2037 | O18: =SUM(B18:M18) -> 0
A19: 2038 | O19: =SUM(B19:M19) -> 0
... A24: 2043 | O24: =SUM(B24:M24) -> 0
A26: Solde Réel
A27: Année | B27: Janvier | C27: Février | D27: Mars | E27: Avril | F27: Mai | G27: Juin | H27: Juillet | I27: Aout | J27: Septembre | K27: Octobre | L27: Novembre | M27: Décembre | N27: Par an
A28: 2024 | B28: 0 | C28: 0 | D28: 0 | E28: 0 | F28: 0 | G28: 0 | H28: 0 | I28: 0 | J28: 0 | K28: 0 | L28: 0 | M28: 0 | N28: =IF(B28<>"",LOOKUP(9^9,B28:M28),"") -> 0
A29: 2025 | B29: 0 | C29: 0 | D29: 0 | E29: 0 | F29: 0 | G29: 0 | H29: 0 | I29: 0 | J29: 0 | K29: 0 | L29: 0 | M29: 0 | N29: =IF(B29<>"",LOOKUP(9^9,B29:M29),"") -> 0
A30: 2026 | B30: 0 | C30: 0 | D30: 0 | E30: 0 | F30: 0 | N30: =IF(B30<>"",LOOKUP(9^9,B30:M30),"") -> 0
A31: 2027 | N31: =IF(B31<>"",LOOKUP(9^9,B31:M31),"")
A32: 2028 | N32: =IF(B32<>"",LOOKUP(9^9,B32:M32),"")
A33: 2029 | N33: =IF(B33<>"",LOOKUP(9^9,B33:M33),"")
A34: 2030 | N34: =IF(B34<>"",LOOKUP(9^9,B34:M34),"")
A35: 2031 | N35: =IF(B35<>"",LOOKUP(9^9,B35:M35),"")
A36: 2032 | N36: =IF(B36<>"",LOOKUP(9^9,B36:M36),"")
A37: 2033 | N37: =IF(B37<>"",LOOKUP(9^9,B37:M37),"")
A38: 2034 | N38: =IF(B38<>"",LOOKUP(9^9,B38:M38),"")
A39: 2035 | N39: =IF(B39<>"",LOOKUP(9^9,B39:M39),"")
A40: 2036 | N40: =IF(B40<>"",LOOKUP(9^9,B40:M40),"")
A41: 2037 | N41: =IF(B41<>"",LOOKUP(9^9,B41:M41),"")
A42: 2038 | N42: =IF(B42<>"",LOOKUP(9^9,B42:M42),"")
... A47: 2043 | N47: =IF(B47<>"",LOOKUP(9^9,B47:M47),"")

Sheet Salaire
B1: Salaire | C1: Solde de départ | D1: 0 | F1: Solde actuel | G1: 0 | I1: Évolution espérée /an | J1: 0.1 | Q1: Stage
C2: Date de départ | D2: 45320
A4: Année | B4: Janvier | C4: Février | D4: Mars | E4: Avril | F4: Mai | G4: Juin | H4: Juillet | I4: Aout | J4: Septembre | K4: Octobre | L4: Novembre | M4: Décembre | N4: Total Sur l'année | O4: Montant Contrat | P4: Dont Net ~ | Q4: Dont Net Après Impot ~
A5: 2024 | B5: 0 | C5: 0 | D5: 0 | E5: 0 | F5: 0 | G5: 0 | H5: 0 | I5: 0 | J5: 0 | K5: 0 | L5: 0 | M5: 0 | N5: =SUM(B5:M5) -> 0 | O5: 0 | P5: =0.78*O5 -> 0 | Q5: =0.9*P5 -> 0
A6: 2025 | B6: 0 | C6: 0 | D6: 0 | E6: 0 | F6: 0 | G6: 0 | H6: 0 | I6: 0 | J6: 0 | K6: 0 | L6: 0 | M6: 0 | N6: =SUM(B6:M6) -> 0 | O6: 0 | P6: =0.78*O6 -> 0 | Q6: =0.88*P6 -> 0
A7: 2026 | B7: 0 | C7: 0 | D7: 0 | E7: 0 | F7: 0 | G7: 0 | N7: =SUM(B7:M7) -> 0
A8: 2027 | N8: =SUM(B8:M8) -> 0
A9: 2028 | N9: =SUM(B9:M9) -> 0
A10: 2029 | N10: =SUM(B10:M10) -> 0
A11: 2030 | N11: =SUM(B11:M11) -> 0
A12: 2031 | N12: =SUM(B12:M12) -> 0
A13: 2032 | N13: =SUM(B13:M13) -> 0
A14: 2033 | N14: =SUM(B14:M14) -> 0
A15: 2034 | N15: =SUM(B15:M15) -> 0
